Workbook

Sheet 说明
A1: 本文件整理自大模组核算原表：辅材 BOM、每平米收口结构、箱体/电源/支架/抱箍/控制箱价目。「每平米收口」样例行是历史底稿，项目报价由 Agent 按招标+规格+本表规则重算本项目收口，不是样例×面积。
A2: 三件套：规格单价表（模组/灯珠/套件及物理箱 SKU）+ 本表（BOM、收口结构、元/㎡箱体与电源/支架/抱箍/控制箱价目）+ 计价 skill。详见方案/场景演示建议口径.md、原表公式与经验配量确认.md。
A3: 压铸铝辅材 / 铁箱辅材：保留原逐项与汇总公式。关键汇总格见各表「总计1平方辅料」「包材总计」「折1平方」行。
A4: 每平米收口：保留结构与对辅材/箱体/电源的公式引用；模组单价列正式稿留空（取规格单价表）。表内「1㎡模组数量」「常规电源数量」为样例/待成本确认的经验位，不作未确认的项目默认取数。
A5: 价目页「箱体」「电源」「支架」「安装抱箍和螺钉」「控制箱」自原表迁入；正式稿单价空/0 由成本维护。规格单价表「箱体单价」仅作物料核对，平方单价中的箱体元/㎡以本册「箱体」为准。报价单「控制系统」取本册「控制箱」汇总（每套），形态加价见报价单 skill。
A6: 不转入屏体清单样例页。招标用抄录面积。供应商名不转入。
A7: BOM 明细与常数加价（如辅材 +20）由成本岗维护，改后同步 skill。

Sheet 压铸铝辅材
A1: BOM层级 | B1: 子项物料编码 | C1: 物料名称 | D1: 含税单价 | E1: 实际数量 | F1: 合计
A2: ..2 | B2: 2200001771 | C2: 箱体组件无凸台（带接收卡DH7508-S）/1000*1000*78-箱体组件/压铸箱体 ADC12 细砂纹黑色 有丝印
A3: ...3 | B3: 1700003743 | C3: 箱体 /CDKXB-YZX-A1D/1000*1000*78 压铸箱（丝印）无凸台/ ADC12 细砂纹黑色 后维护 | E3: 1 | F3: =D3*E3
A4: ...3 | B4: 1700002769 | C4: 接收卡安装板/CDKXB-YZX-A3/300*240*1.5 /AL5052本色 | E4: 1 | F4: =D4*E4
A5: ...3 | B5: 1700002770 | C5: 电源 MRV570-1接收卡 MON300点检卡 共用安装板/CDKXB-YZX-A4/250*250*1.5 / AL5052本色 | E5: 1 | F5: =D5*E5
C6: 安装件总计 | F6: =SUM(F4:F5)
A9: ...3 | B9: 1600000335 | C9: 外六角十字螺钉/M4*8/304不锈钢（盐雾时间超过48H)A2-70/本色 | E9: 144 | F9: =D9*E9
A10: ...3 | B10: 1600000061 | C10: 3合1螺钉/M3*8/碳钢/镀白锌 | E10: 24 | F10: =D10*E10
A11: ...3 | B11: 1600000027 | C11: 圆头十字螺钉/M4*8/碳钢/镀白锌 | E11: 2 | F11: =D11*E11
A12: ...3 | B12: 1600000063 | C12: 3合1螺钉/M4*8/碳钢/镀白锌 | E12: 4 | F12: =D12*E12
A13: ...3 | B13: 1000000989 | C13: 接收卡/NV7508 | E13: 1
A14: ...3 | B14: 1300000104 | C14: 接线排/TB2504/4位 | E14: 1 | F14: =D14*E14
A15: ...3 | B15: 1400000152 | C15: 16P 2.54mm-2*8P插座带蝴蝶扣同向排线/200mm/镀锡铜7*0.12mm | E15: 1 | F15: =D15*E15
A16: ...3 | B16: 1400000070 | C16: 16P 2.54mm-2*8P插座带蝴蝶扣同向排线/330mm/镀锡铜7*0.12mm | E16: 3 | F16: =D16*E16
A17: ...3 | B17: 1400000141 | C17: 16P 2.54mm-2*8P插座带蝴蝶扣同向排线/350mm/镀锡铜7*0.12mm | E17: 1 | F17: =D17*E17
A18: ...3 | B18: 1400000071 | C18: 16P 2.54mm-2*8P插座带蝴蝶扣同向排线/600mm/镀锡铜7*0.12mm | E18: 1 | F18: =D18*E18
A19: ...3 | B19: 1400000073 | C19: 16P 2.54mm-2*8P插座带蝴蝶扣同向排线/800mm/镀锡铜7*0.12mm | E19: 2 | F19: =D19*E19
A20: ...3 | B20: 1400000228 | C20: 一拖四5V单元板电源线/主线长0.98m 分支线长0.12m 间隔0.26m焊接分支线 接线叉SNB2-4 /分支线BVR铜软1mm² 主线国标BVR铜软4mm² | E20: 2 | F20: =D20*E20
A21: ...3 | B21: 2200001070 | C21: 铜芯聚氯乙烯绝缘连接软电线/RV1mm² 线长400mm/带SNB2-4 SNB2-3接线叉子/黑色 | E21: 1 | F21: =D21*E21
A22: ....4 | B22: 1400000045 | C22: 铜芯聚氯乙烯绝缘连接软电线/RV1mm²电压300-500V/黑色 | F22: =D22*E22
A23: ....4 | B23: 1300000130 | C23: 冷压接线端子/SNB2-4/国标紫铜U型/16*6.4*0.8mm | F23: =D23*E23
A24: ....4 | B24: 1300000129 | C24: 冷压接线端子/SNB2-3/国标紫铜U型/16*5.7*0.8mm | F24: =D24*E24
A25: ....4 | B25: 1700000078 | C25: 热缩管φ4/黑色 | F25: =D25*E25
A26: ...3 | B26: 2200001071 | C26: 铜芯聚氯乙烯绝缘连接软电线/RV1mm² 线长400mm/带SNB2-4 SNB2-3接线叉子/红色 | E26: 1 | F26: =D26*E26
A27: ....4 | B27: 1400000046 | C27: 铜芯聚氯乙烯绝缘连接软电线/RV1mm²电压300-500V/红色 | F27: =D27*E27
A28: ....4 | B28: 1300000130 | C28: 冷压接线端子/SNB2-4/国标紫铜U型/16*6.4*0.8mm | F28: =D28*E28
A29: ....4 | B29: 1300000129 | C29: 冷压接线端子/SNB2-3/国标紫铜U型/16*5.7*0.8mm | F29: =D29*E29
A30: ....4 | B30: 1700000078 | C30: 热缩管φ4/黑色 | F30: =D30*E30
A31: ...3 | B31: 2200001072 | C31: 铜芯聚氯乙烯绝缘连接软电线/RV1.5mm²线长300mm/带RNB2-4黄绿色 | E31: 2 | F31: =D31*E31
A32: ....4 | B32: 1400000061 | C32: 铜芯聚氯乙烯绝缘阻燃软电线/ZR BVR1*1.5mm²电压450-750V/黄绿色 | F32: =D32*E32
A33: ....4 | B33: 1300000127 | C33: 冷压接线端子/RNB2-4/国标紫铜O型/14.4*6.6*0.8mm | F33: =D33*E33
A34: ...3 | B34: 2200001073 | C34: 铜芯聚氯乙烯绝缘连接软电线/RV1.5mm²线长200mm/带RNB2-4 SNB2-4黄绿色 | E34: 1 | F34: =D34*E34
A35: ....4 | B35: 1400000061 | C35: 铜芯聚氯乙烯绝缘阻燃软电线/ZR BVR1*1.5mm²电压450-750V/黄绿色 | F35: =D35*E35
A36: ....4 | B36: 1300000127 | C36: 冷压接线端子/RNB2-4/国标紫铜O型/14.4*6.6*0.8mm | F36: =D36*E36
A37: ....4 | B37: 1300000130 | C37: 冷压接线端子/SNB2-4/国标紫铜U型/16*6.4*0.8mm | F37: =D37*E37
A38: ....4 | B38: 1700000078 | C38: 热缩管φ4/黑色 | F38: =D38*E38
A39: ...3 | B39: 2200001074 | C39: 聚氯乙烯绝缘护套电缆电线/RVV3*1.5mm²线长1000mm（内芯棕色、蓝色、黄绿色）/带SNB2-4/黑色 | E39: 1 | F39: =D39*E39
A40: ....4 | B40: 1400000001 | C40: 聚氯乙烯绝缘护套电缆电线/RVV3*1.5mm²电压300-500V（内芯棕色、蓝色、黄绿色 多股软芯线）/黑色 | F40: =D40*E40
A41: ....4 | B41: 1300000130 | C41: 冷压接线端子/SNB2-4/国标紫铜U型/16*6.4*0.8mm | F41: =D41*E41
A42: ....4 | B42: 1700000078 | C42: 热缩管φ4/黑色 | F42: =D42*E42
...

Sheet 铁箱辅材
A1: BOM层级 | B1: 子项物料编码 | C1: 物料名称 | D1: 含税单价 | E1: 价税合计 | F1: 标准用量 | G1: 实际数量
A2: 0 | B2: 3000001526 | C2: 门架式可变信息标志（全彩）/P10.416 1R1G1B 500*250/CDCKB10+MJ01/10100*1100*180/SGCC=1.5 蓝灰色(钣金箱体） 2025-OS039 K945回城方向 | F2: 1 | G2: 1
A3: .1 | B3: 2300001420 | C3: 门架式可变信息标志（全彩）/P10.416 1R1G1B 500*250/CDCKB10+MJ01/10100*1100*180/SGCC=1.5 蓝灰色(钣金箱体） 2025-OS039 祼机 | F3: 1 | G3: 1
A4: ..2 | B4: 2200001588 | C4: 屏体/CDKXB-MJ33-C1/10100*1100*180/SGCC=1.5MM 蓝灰色 | F4: 1 | G4: 1
C5: 箱体1平方单价 | E5: =E4/10
A7: ..2 | B7: 1600000100 | C7: 3合1螺钉/M3*6/碳钢/包黑色 | F7: 120 | G7: 120
A8: ..2 | B8: 1600000063 | C8: 3合1螺钉/M4*8/碳钢/镀白锌 | F8: 40 | G8: 40
A9: ..2 | B9: 1600000061 | C9: 3合1螺钉/M3*8/碳钢/镀白锌 | F9: 132 | G9: 132
A10: ..2 | B10: 1600000026 | C10: 圆头十字螺钉/M4*6/碳钢/镀白锌 | F10: 1440 | G10: 1440
A11: ..2 | B11: 1600000027 | C11: 圆头十字螺钉/M4*8/碳钢/镀白锌 | F11: 28 | G11: 28
A12: ..2 | B12: 2200001584 | C12: 单元板（模组）P10.416直插模组/全彩1R1G1B/347椭圆灯珠/48*24/驱动芯片16289S/75接口/静态/正面灌胶/工作电压DC5V±10%/亮度≥15000cd/㎡/视认角度≤65°/500*250*27/VEN00061/VEN00143 | F12: 80 | G12: 80
A13: ...3 | B13: 1000000734 | C13: 插装发光二极管/红色/347椭圆/HZ-347PR3H0F1XE-X2/发光强度1000-1200mcd/波长620-625/电压1.7-2.1V/5mA/视角65℃/带卡口/VEN00061 | F13: 92160 | G13: 92160
A14: ...3 | B14: 1000000755 | C14: 插装发光二极管/绿色/347椭圆/HZ-347PG3H0F1TE-X1/发光强度2300-2500mcd 2500-2800mcd两段50%比例混用/波长528-531 531-534两段50%比例混用/电压2.4-2.8V/5mA/视角65℃/带卡口/VEN00061 | F14: 92160 | G14: 92160
A15: ...3 | B15: 1000000736 | C15: 插装发光二极管/蓝色/347椭圆/HZ-347PB3H0F1TE-X2/发光强度460-500mcd 500-550mcd/波长466-469nm 469-472nm两段50%比例混用/电压2.4-2.8V/5mA/视角65℃/带卡口/VEN00061 | F15: 92160 | G15: 92160
A16: ...3 | B16: 1700003210 | C16: P10.416底壳/CDKXB-YZMZ-B1/500*250*18 /VEN00452 PC+15%GF 本色 | F16: 80 | G16: 80
A17: ...3 | B17: 1700003211 | C17: P10.416面罩/CDKXB-YZMZ-B2/250*250 /VEN00452 PC+15%GF 本色 | F17: 160 | G17: 160
A18: ...3 | B18: 1700003212 | C18: 模组胶圈/CDKXB-YZMZ-B3/500*250*3.4 /VEN00452 硅橡胶 30度 本色 | F18: 80 | G18: 80
... A55: ..2 | B55: 1800000436 | C55: 防水亚银标签纸/50 *125 *300/进口背胶 | F55: 1 | G55: 1
A56: ..2 | B56: 1800000274 | C56: 可变信息标志通用使用说明书 | D56: 0 | F56: 1 | G56: 1
E57: =SUM(E7:E56)
C58: 1平方辅料单价 | E58: =E57/10
A60: ..2 | B60: 1800000165 | C60: 可变信息标志纸箱/CDKXB-MJ05F-F6/内2010*1110*220 外2025*1125*235/ 5层瓦楞 本色 | F60: 3 | G60: 3
A61: ..2 | B61: 1800000166 | C61: 可变信息标志纸箱/CDKXB-MJ05F-F7/内2060*1110*220 外2075*1125*235/ 5层瓦楞 本色 | F61: 2 | G61: 2
E62: =SUM(E60:E61)
C63: 包材总计 | E63: =E62/10+2
A65: .1 | B65: 1700000358 | C65: 两孔几字连接板-M12/CDTPJ-AZL-A6/130*40*39*4/热镀锌=4MM | F65: 18 | G65: 18
A66: .1 | B66: 1700000760 | C66: 单孔几字连接板-M12/CDTPJ-AZL-A6-2/90*50*39*4/SGCC=4MM 热镀锌本色 | F66: 4 | G66: 4
A67: .1 | B67: 1600000087 | C67: 不锈钢螺母/M12/不锈钢 A2-70/本色 | F67: 36 | G67: 36
A68: .1 | B68: 1600000051 | C68: 不锈钢平垫/M12/不锈钢 A2-70/本色 | F68: 80 | G68: 80
A69: .1 | B69: 1600000045 | C69: 不锈钢弹垫/M12/不锈钢 A2-70/本色 | F69: 60 | G69: 60
A70: .1 | B70: 1600000135 | C70: 外六角螺栓/M12*50/不锈钢 A2-70/本色 | F70: 20 | G70: 20
A71: .1 | B71: 1600000038 | C71: 外六角螺栓/M12*30/不锈钢 A2-70/本色 | F71: 56 | G71: 56
A72: .1 | B72: 1600000183 | C72: 尼龙圆形平垫片（硬性材料）/12*24*2mm/黑色 | F72: 32 | G72: 32
E73: =SUM(E65:E72)
C74: 抱箍螺钉1平方 | E74: =E73/10+5

Sheet 箱体
A1: 箱体单价
A2: 序号 | B2: 名称 | C2: 数量 | D2: 单位 | E2: 箱体单价 | F2: 配件单价 | G2: 综合单价 | H2: 备注
A3: 1 | B3: 压铸铝箱体 | C3: 1 | D3: ㎡ | F3: 0 | G3: =E3+F3 | H3: 不含包边
A4: 2 | B4: 镀锌钢板箱体 | C4: 1 | D4: ㎡ | G4: =E4+F4 | H4: 不含包边
A5: 3 | B5: 镀锌钢板箱体 | C5: 1 | D5: ㎡ | G5: =E5+F5 | H5: 含包边
A6: 4

Sheet 电源
A1: 电源单价
A2: 序号 | B2: 规格 | C2: 功率因素 | D2: 温度 | E2: 数量 | F2: 单位 | G2: 单价 | H2: 备注
A3: 1 | B3: 100W/5V | C3: 常规 | D3: 常规 | E3: 1 | F3: 个
A4: 2 | B4: 100W/5V | C4: 高功率因素 | D4: 常规 | E4: 1 | F4: 个
A5: 3 | B5: 100W/5V | C5: 高功率因素 | D5: 低温 | E5: 1 | F5: 个
A6: 5 | B6: 110W/3.2V+3.8V | C6: 高功率因素 | D6: 常规 | E6: 1 | F6: 个
A7: 6 | B7: 110W/3.2V+3.8V | C7: 高功率因素 | D7: 低温 | E7: 1 | F7: 个
A8: 5 | B8: 175W/3.2V+3.8V | C8: 高功率因素 | D8: 常规 | E8: 1 | F8: 个
A9: 6 | B9: 175W/3.2V+3.8V | C9: 高功率因素 | D9: 低温 | E9: 1 | F9: 个
A10: 7 | B10: 200W/5V | C10: 常规 | D10: 常规 | E10: 1 | F10: 个 | H10: 44厚款
A11: 8 | B11: 200W/5V | C11: 高功率因素 | D11: 常规 | E11: 1 | F11: 个
A12: 9 | B12: 200W/5V | C12: 高功率因素 | D12: 低温 | E12: 1 | F12: 个
A13: 5 | B13: 175W/3.2V+3.8V | C13: 高功率因素 | D13: 常规 | E13: 1 | F13: 个
A14: 6 | B14: 175W/3.2V+3.8V | C14: 高功率因素 | D14: 低温 | E14: 1 | F14: 个
A15: 13 | B15: 300W/5V | C15: 常规 | D15: 常规 | E15: 1 | F15: 个
A16: 14 | B16: 300W/5V | C16: 高功率因素 | D16: 常规 | E16: 1 | F16: 个
A17: 15 | B17: 300W/5V | C17: 高功率因素 | D17: 低温 | E17: 1 | F17: 个

Sheet 支架
A1: 支架单价
A2: 序号 | B2: 名称 | C2: 数量 | D2: 单位 | E2: 支架单价 | F2: 螺钉配件单价 | G2: 综合单价 | H2: 备注
A3: 1 | B3: 收费大棚吊装吊架 | C3: 1 | D3: 平方 | E3: 400 | F3: 30 | G3: =E3+F3
A4: 2 | B4: 收费大棚背部支架 | C4: 1 | D4: 平方 | G4: =E4+F4
A5: 3 | B5: 路段1米高支撑架 | C5: 1 | D5: 平方 | E5: 110 | F5: =安装抱箍和螺钉!L5 | G5: =E5+F5
A6: 4 | B6: 路段2米高支撑架 | C6: 1 | D6: 平方 | E6: 160 | F6: =安装抱箍和螺钉!L6 | G6: =E6+F6
A7: 5 | B7: 路段1㎡支撑架 | C7: 1 | D7: 套 | E7: 400 | F7: =安装抱箍和螺钉!L7 | G7: =E7+F7
A8: 6 | B8: 路段2㎡支撑架 | C8: 1 | D8: 套 | E8: 400 | F8: =安装抱箍和螺钉!L8 | G8: =E8+F8
A9: 6 | B9: 路段4㎡支撑架 | C9: 1 | D9: 套 | E9: 400 | F9: =安装抱箍和螺钉!L9 | G9: =E9+F9
A10: 7 | B10: 悬臂含走道支架 | C10: 1 | D10: 套 | F10: =安装抱箍和螺钉!L9 | G10: =E10+F10 | H10: 3.2*1.6
A11: 8 | B11: 悬臂含走道支架 | C11: 1 | D11: 套 | F11: =安装抱箍和螺钉!L10 | G11: =E11+F11 | H11: 4*2
A12: 9 | B12: 洞内屏2支架2节支架 | C12: 1 | D12: 套 | E12: =E24 | F12: =E35+8*10 | G12: =E12+F12 | H12: 含膨胀螺栓
A13: 10 | B13: 洞内屏2支架3节支架 | C13: 1 | D13: 套 | E13: =E43 | F13: =E53+8*10 | G13: =E13+F13 | H13: 含膨胀螺栓
A14: 11 | B14: 洞内屏3支架3节支架 | C14: 1 | D14: 套 | E14: =E63 | F14: =E73+12*10 | G14: =E14+F14 | H14: 含膨胀螺栓
A15: 12 | B15: 洞内侧壁1.6*3.2支架 | C15: 1 | D15: 套 | E15: =400*1.6*3.2 | F15: =1.6*3.2*3*16 | G15: =E15+F15 | H15: 含膨胀螺栓
A16: 13 | B16: 洞内侧壁1*2支架 | C16: 1 | D16: 套 | E16: =400*2 | F16: =1*2*4*16 | G16: =E16+F16 | H16: 含膨胀螺栓
A17: 14 | B17: 服务区 | C17: 1 | D17: 平方 | E17: 600 | F17: 50 | G17: =E17+F17
A19: 洞内两支架两节
A20: BOM层级 | B20: 子项物料编码 | C20: 物料名称 | D20: 含税单价 | E20: 价税合计 | F20: 标准用量 | G20: 实际数量 | H20: 替代方式
A21: 0 | B21: 3000001603 | C21: 洞内拱顶可变信息标志（双色)/P25 2R1G 200*200/CDCKB25+DN01/2500*1300*200/SGCC=1.5 蓝灰色(钣金箱体）2025-BS013 | D21: 10413.57 | E21: 10413.57 | F21: 1 | G21: 1
A22: .1 | B22: 1700000482 | C22: 洞内吊架顶安装板/CDTPJ-AZL-C2B/280*200*295/Q235=20MM 热镀锌本色 | D22: 167.96 | E22: 335.92 | F22: 2 | G22: 2
A23: .1 | B23: 1700000107 | C23: 洞内吊架下安装支架/CDTPJ-AZL-C4/300*200*300/槽钢+Q235 热镀锌本色 | D23: 131.12 | E23: 262.24 | F23: 2 | G23: 2
C24: 2支架成本总计 | E24: =SUM(E22:E23)
A26: 洞内两支架两节
A27: .1 | B27: 1600000048 | C27: 不锈钢弹垫/M24/不锈钢 A2-70/本色 | D27: 0.57 | E27: 2.28 | F27: 4 | G27: 4
A28: .1 | B28: 1600000054 | C28: 不锈钢平垫/M24/不锈钢 A2-70/本色 | D28: 0.71 | E28: 5.68 | F28: 8 | G28: 8
A29: .1 | B29: 1600000007 | C29: 螺母/M24/不锈钢；A2-70/本色 | D29: 2.35 | E29: 18.8 | F29: 8 | G29: 8
A30: .1 | B30: 1600000042 | C30: 外六角螺栓/M24*80/不锈钢 A2-70/本色 | D30: 8.1 | E30: 32.4 | F30: 4 | G30: 4
A31: .1 | B31: 1600000041 | C31: 外六角螺栓/M18*60/不锈钢 A2-70/本色 | D31: 3.36 | E31: 26.88 | F31: 8 | G31: 8
A32: .1 | B32: 1600000047 | C32: 不锈钢弹垫/M18/不锈钢 A2-70/本色 | D32: 0.22 | E32: 1.76 | F32: 8 | G32: 8
A33: .1 | B33: 1600000053 | C33: 不锈钢平垫/M18/不锈钢 A2-70/本色 | D33: 0.33 | E33: 5.28 | F33: 16 | G33: 16
A34: .1 | B34: 1600000006 | C34: 螺母/M18/不锈钢；A2-70/本色 | D34: 1.05 | E34: 8.4 | F34: 8 | G34: 8
C35: 总计螺钉 | E35: =SUM(E27:E34)
A37: 洞内两支架三节
A38: BOM层级 | B38: 子项物料编码 | C38: 物料名称 | D38: 含税单价 | E38: 价税合计 | F38: 标准用量 | G38: 实际数量
A39: 0 | B39: 3000001744 | C39: 洞内拱顶可变信息标志（双色)/P25 2R1G 400*200/CDCKB25+DN01/2500*1300*200/SGCC=1.5 蓝灰色(钣金箱体）2025-S561 | D39: 10132.8 | E39: 10132.8 | F39: 1 | G39: 1
A40: .1 | B40: 1700000482 | C40: 洞内吊架顶安装板/CDTPJ-AZL-C2B/280*200*295/Q235=20MM 热镀锌本色 | D40: 167.96 | E40: 335.92 | F40: 2 | G40: 2
A41: .1 | B41: 1700000107 | C41: 洞内吊架下安装支架/CDTPJ-AZL-C4/300*200*300/槽钢+Q235 热镀锌本色 | D41: 131.12 | E41: 262.24 | F41: 2 | G41: 2
A42: .1 | B42: 1700000106 | C42: 洞内吊架中间调节槽钢/CDTPJ-AZL-C3/120*53*450/槽钢 热镀锌本色 | D42: 45.799999 | E42: 91.6 | F42: 2 | G42: 2
C43: 3件套支架总计 | E43: =SUM(E40:E42)
...

Sheet 安装抱箍和螺钉
A1: 安装抱箍和螺钉单价
A2: 序号 | B2: 名称 | C2: 抱箍数量 | D2: 抱箍单价 | E2: 抱箍合计 | F2: 抱箍数量 | G2: 几字安装件单价 | H2: 几字安装件合计 | I2: 螺钉配件数量 | J2: 螺钉配件单价 | K2: 螺钉配件合计 | L2: 综合价格 | M2: 备注
A3: 1 | B3: 收费大棚吊装吊架 | C3: 1 | E3: =C3*D3 | F3: 1 | H3: =G3*F3 | I3: 1 | K3: =J3*I3 | L3: =E3+H3+K3
A4: 2 | B4: 收费大棚背部支架 | C4: 1 | E4: =C4*D4 | F4: 1 | H4: =G4*F4 | I4: 1 | K4: =J4*I4 | L4: =E4+H4+K4
A5: 3 | B5: 路段1米高支撑架 | C5: 1 | E5: =C5*D5 | F5: 1 | H5: =G5*F5 | I5: 1 | K5: =J5*I5 | L5: =E5+H5+K5
A6: 4 | B6: 路段2米高支撑架 | C6: 1 | E6: =C6*D6 | F6: 1 | H6: =G6*F6 | I6: 1 | K6: =J6*I6 | L6: =E6+H6+K6
A7: 5 | B7: 路段1㎡支撑架 | C7: 1 | E7: =C7*D7 | F7: 1 | H7: =G7*F7 | I7: 1 | K7: =J7*I7 | L7: =E7+H7+K7
A8: 6 | B8: 路段2㎡支撑架 | C8: 1 | E8: =C8*D8 | F8: 1 | H8: =G8*F8 | I8: 1 | K8: =J8*I8 | L8: =E8+H8+K8
A9: 7 | B9: 悬臂含走道支架3.2*1.6 | C9: 1 | E9: =C9*D9 | F9: 1 | H9: =G9*F9 | I9: 1 | K9: =J9*I9 | L9: =E9+H9+K9
A10: 8 | B10: 悬臂含走道支架4*2 | C10: 1 | E10: =C10*D10 | F10: 1 | H10: =G10*F10 | I10: 1 | K10: =J10*I10 | L10: =E10+H10+K10
A11: 9 | B11: 洞内屏2支架2节支架 | C11: 1 | E11: =C11*D11 | F11: 1 | H11: =G11*F11 | I11: 1 | K11: =J11*I11 | L11: =E11+H11+K11
A12: 10 | B12: 洞内屏2支架3节支架 | C12: 1 | E12: =C12*D12 | F12: 1 | H12: =G12*F12 | I12: 1 | K12: =J12*I12 | L12: =E12+H12+K12
A13: 11 | B13: 洞内屏3支架3节支架 | C13: 1 | E13: =C13*D13 | F13: 1 | H13: =G13*F13 | I13: 1 | K13: =J13*I13 | L13: =E13+H13+K13
A14: 12 | B14: 洞内侧壁1.6*3.2支架 | C14: 1 | E14: =C14*D14 | F14: 1 | G14: =G13 | H14: =G14*F14 | I14: 1 | J14: =J13 | K14: =J14*I14 | L14: =E14+H14+K14
A15: 13 | B15: 洞内侧壁1*2支架 | C15: 1 | E15: =C15*D15 | F15: 1 | G15: =G14 | H15: =G15*F15 | I15: 1 | J15: =J14 | K15: =J15*I15 | L15: =E15+H15+K15

Sheet 控制箱
A1: BOM层级 | B1: 子项物料编码 | C1: 物料名称 | D1: 含税单价 | E1: 合计 | F1: 数量
A2: .1 | B2: 3000001386 | C2: 可变信息标志控制箱（单相含控制卡--无信号防雷版）/KXB-10P-A1-KZX+KZ03/400*610*140/SGCC=1.2 户外7035 | F2: 1
A3: ..2 | B3: 2300001283 | C3: 可变信息标志控制箱（单相含控制卡-无信号防雷版）/KXB-10P-A1-KZX+KZ03/400*610*140/SGCC=1.2 户外7035 裸机 | F3: 1
A4: ...3 | B4: 2200000649 | C4: 服务区情报板单相控制箱（背抱安装）箱体/KXB-KZ03D-D1/400*610*140/SGCC=1.2 户外7035 | F4: 1
A5: ...3 | B5: 1000000932 | C5: 多媒体播放盒/GX30T | F5: 1
A6: ...3 | B6: 1500000042 | C6: 开关电源/LM25-23B05/5V/5A 25W/效率88%/工作温度范围：-30℃to +70℃/VEN00112 | F6: 1
A7: ...3 | B7: 1700000010 | C7: 单相电源防雷器/CD-D/AC20-2（丝印创迪LOGO）/VEN00054 | F7: 1
A8: ...3 | B8: 1900000039 | C8: 光探头/ALP050-1.5M-P/CON4-2.54插头 | F8: 1
A9: ...3 | B9: 1000000515 | C9: 空开/DZ47SC63(63A,1P)/N | F9: 1
A10: ...3 | B10: 1000000464 | C10: 空开/DZ47sN1C32(32A,1P)/N | F10: 3
A11: ...3 | B11: 1300000116 | C11: AC30模数化插座/250V/10-16A/3孔 | F11: 1
A12: ...3 | B12: 1600000102 | C12: 过线圈/PG29/尼龙/白色 | F12: 4
A13: ...3 | B13: 1000000480 | C13: 空开背条/L=1000*35*7.5mm/C45导轨，1mm厚，国标 | F13: 0.4
... A51: .1 | B51: 1700003261 | C51: PA尼龙波纹管（闭口）/AD34.5内径29mm外径34.5mm PA6尼龙/工作温度-40℃-100℃/黑色 | F51: 4
C52: 总计辅材和箱体10平方 | E52: =SUM(E4:E51)

Sheet 每平米收口
A1: P10.416情报板屏单价(1㎡单价)
A2: 序号 | B2: 材料 | C2: 高度屏体安装高度 | D2: 灯珠 | E2: 1㎡模组数量 | F2: 模组单价 | G2: 1㎡模组价格合计 | H2: 箱体单价 | I2: 常规电源数量 | J2: 电源单价 | K2: 电源合计 | L2: 安装支架（选配） | M2: 安装抱箍和螺钉 | N2: 包材 | O2: 辅材 | P2: 总计 | Q2: 备注
A3: 1.1 | B3: 压铸铝箱体不含包边（含包边加110元/㎡） | C3: 1m | D3: 310F5 /1R1G | E3: 8 | G3: =E3*F3 | H3: =箱体!G3 | I3: 2 | J3: =电源!G11 | K3: =J3*I3 | N3: =压铸铝辅材!F60 | O3: =压铸铝辅材!F56+压铸铝辅材!E80+20 | P3: =G3+H3+K3+L3+M3+N3+O3 | Q3: 模组单价见规格单价表；箱体/电源见本册价目
A4: 1.2 | D4: 310F5 /1R1G1B | E4: =E3 | G4: =E4*F4 | H4: =H3 | I4: =I3 | J4: =J3 | K4: =J4*I4 | L4: =L3 | M4: =M3 | N4: =N3 | O4: =O3 | P4: =G4+H4+K4+L4+M4+N4+O4 | Q4: 模组单价见规格单价表；箱体/电源见本册价目
A5: 1.3 | B5: 镀锌钢板箱体含包边 | C5: 1m | D5: 310F5 /1R1G | E5: 8 | F5: =F3 | G5: =E5*F5 | H5: =箱体!G5 | I5: 2 | J5: =J3 | K5: =J5*I5 | N5: =铁箱辅材!E63 | O5: =铁箱辅材!E58+20 | P5: =G5+H5+K5+L5+M5+N5+O5 | Q5: 模组单价见规格单价表；箱体/电源见本册价目
A6: 1.4 | D6: 310F5 /1R1G1B | E6: =E5 | F6: =F4 | G6: =E6*F6 | H6: =H5 | I6: =I5 | J6: =J5 | K6: =J6*I6 | L6: =L5 | M6: =M5 | N6: =N5 | O6: =O5 | P6: =G6+H6+K6+L6+M6+N6+O6 | Q6: 模组单价见规格单价表；箱体/电源见本册价目
A7: P15.625情报板屏单价(1㎡单价)
A8: 序号 | B8: 材料 | C8: 高度屏体安装高度 | D8: 灯珠 | E8: 1㎡模组数量 | F8: 模组单价 | G8: 1㎡模组价格合计 | H8: 箱体单价 | I8: 常规电源数量 | J8: 电源单价 | K8: 电源合计 | L8: 安装支架（选配） | M8: 安装抱箍和螺钉 | N8: 包材 | O8: 辅材 | P8: 总计 | Q8: 备注
A9: 2.1 | B9: 压铸铝箱体不含包边（含包边加110元/㎡） | C9: 1m | D9: 310F5 /1R1G | E9: 8 | G9: =E9*F9 | H9: =H3 | I9: 2 | J9: =电源!G10 | K9: =J9*I9 | L9: =L3 | M9: =M3 | N9: =N3 | O9: =O3 | P9: =G9+H9+K9+L9+M9+N9+O9 | Q9: 模组单价见规格单价表；箱体/电源见本册价目
A10: 2.2 | D10: 310F5 /1R1G1B | E10: 8 | G10: =E10*F10 | H10: =H9 | I10: =I9 | J10: =J9 | K10: =J10*I10 | L10: =L9 | M10: =M9 | N10: =N9 | O10: =O9 | P10: =G10+H10+K10+L10+M10+N10+O10 | Q10: 模组单价见规格单价表；箱体/电源见本册价目
A11: 2.3 | D11: 310F5 /2R1G | E11: 8 | G11: =E11*F11 | H11: =H10 | I11: =I10 | J11: =J10 | K11: =J11*I11 | L11: =L10 | M11: =M10 | N11: =N10 | O11: =O10 | P11: =G11+H11+K11+L11+M11+N11+O11 | Q11: 模组单价见规格单价表；箱体/电源见本册价目
A12: 2.4 | D12: 310F5 /2R1G1B | E12: =E9 | G12: =E12*F12 | H12: =H11 | I12: =I11 | J12: =J11 | K12: =J12*I12 | L12: =L11 | M12: =M11 | N12: =N11 | O12: =O11 | P12: =G12+H12+K12+L12+M12+N12+O12 | Q12: 模组单价见规格单价表；箱体/电源见本册价目
A13: 2.5 | B13: 镀锌钢板箱体含包边 | C13: 1m | D13: 310F5 /1R1G | E13: 8 | F13: =F9 | G13: =E13*F13 | H13: =H5 | I13: =I12 | J13: =J12 | K13: =J13*I13 | L13: =L5 | M13: =M5 | N13: =N5 | O13: =O5 | P13: =G13+H13+K13+L13+M13+N13+O13 | Q13: 模组单价见规格单价表；箱体/电源见本册价目
A14: 2.6 | D14: 310F5 /1R1G1B | E14: 8 | F14: =F10 | G14: =E14*F14 | H14: =H13 | I14: =I13 | J14: =J13 | K14: =J14*I14 | L14: =L13 | M14: =M13 | N14: =N13 | O14: =O13 | P14: =G14+H14+K14+L14+M14+N14+O14 | Q14: 模组单价见规格单价表；箱体/电源见本册价目
A15: 2.7 | D15: 310F5 /2R1G | E15: 8 | F15: =F11 | G15: =E15*F15 | H15: =H14 | I15: =I14 | J15: =J14 | K15: =J15*I15 | L15: =L14 | M15: =M14 | N15: =N14 | O15: =O14 | P15: =G15+H15+K15+L15+M15+N15+O15 | Q15: 模组单价见规格单价表；箱体/电源见本册价目
A16: 2.8 | D16: 310F5 /2R1G1B | E16: =E13 | F16: =F12 | G16: =E16*F16 | H16: =H15 | I16: =I15 | J16: =J15 | K16: =J16*I16 | L16: =L15 | M16: =M15 | N16: =N15 | O16: =O15 | P16: =G16+H16+K16+L16+M16+N16+O16 | Q16: 模组单价见规格单价表；箱体/电源见本册价目
A17: P20.833情报板屏单价(1㎡单价)
A18: 序号 | B18: 材料 | C18: 高度屏体安装高度 | D18: 灯珠 | E18: 1㎡模组数量 | F18: 模组单价 | G18: 1㎡模组价格合计 | H18: 箱体单价 | I18: 常规电源数量 | J18: 电源单价 | K18: 电源合计 | L18: 安装支架（选配） | M18: 安装抱箍和螺钉 | N18: 包材 | O18: 辅材 | P18: 总计 | Q18: 备注
A19: 3.1 | B19: 压铸铝箱体不含包边（含包边加110元/㎡） | C19: 1m | D19: 310F5 /1R1G1B | E19: 8 | G19: =E19*F19 | H19: =H3 | I19: 2 | J19: =电源!G10 | K19: =J19*I19 | L19: =L3 | M19: =M3 | N19: =N3 | O19: =O3 | P19: =G19+H19+K19+L19+M19+N19+O19 | Q19: 模组单价见规格单价表；箱体/电源见本册价目
A20: 3.2 | D20: 310F5 /2R1G | E20: =E19 | G20: =E20*F20 | H20: =H19 | I20: =I19 | J20: =J19 | K20: =J20*I20 | L20: =L19 | M20: =M19 | N20: =N19 | O20: =O19 | P20: =G20+H20+K20+L20+M20+N20+O20 | Q20: 模组单价见规格单价表；箱体/电源见本册价目
A21: 3.3 | D21: 310F5 /2R1G1B | E21: =E20 | G21: =E21*F21 | H21: =H20 | I21: =I20 | J21: =J20 | K21: =J21*I21 | L21: =L20 | M21: =M20 | N21: =N20 | O21: =O20 | P21: =G21+H21+K21+L21+M21+N21+O21 | Q21: 模组单价见规格单价表；箱体/电源见本册价目
A22: 3.4 | B22: 镀锌钢板箱体含包边 | C22: 1m | D22: 310F5 /1R1G1B | E22: =E21 | F22: =F19 | G22: =E22*F22 | H22: =H5 | I22: =I21 | J22: =J21 | K22: =J22*I22 | L22: =L5 | M22: =M5 | N22: =N5 | O22: =O5 | P22: =G22+H22+K22+L22+M22+N22+O22 | Q22: 模组单价见规格单价表；箱体/电源见本册价目
A23: 3.5 | D23: 310F5 /2R1G | E23: =E22 | F23: =F20 | G23: =E23*F23 | H23: =H22 | I23: =I22 | J23: =J22 | K23: =J23*I23 | L23: =L22 | M23: =M22 | N23: =N22 | O23: =O22 | P23: =G23+H23+K23+L23+M23+N23+O23 | Q23: 模组单价见规格单价表；箱体/电源见本册价目
A24: 3.6 | D24: 310F5 /2R1G1B | E24: =E23 | F24: =F21 | G24: =E24*F24 | H24: =H23 | I24: =I23 | J24: =J23 | K24: =J24*I24 | L24: =L23 | M24: =M23 | N24: =N23 | O24: =O23 | P24: =G24+H24+K24+L24+M24+N24+O24 | Q24: 模组单价见规格单价表；箱体/电源见本册价目
A25: P25情报板屏单价(1㎡单价)
A26: 序号 | B26: 材料 | C26: 高度屏体安装高度 | D26: 灯珠 | E26: 1㎡模组数量 | F26: 模组单价 | G26: 1㎡模组价格合计 | H26: 箱体单价 | I26: 常规电源数量 | J26: 电源单价 | K26: 电源合计 | L26: 安装支架（选配） | M26: 安装抱箍和螺钉 | N26: 包材 | O26: 辅材 | P26: 总计 | Q26: 备注
A27: 4.1 | B27: 压铸铝箱体不含包边（含包边加110元/㎡） | C27: 1m | D27: 310F5 /2R1G | E27: 8 | G27: =E27*F27 | H27: =H3 | I27: =I3 | J27: =电源!G10 | K27: =K3 | L27: =L3 | M27: =M3 | N27: =N3 | O27: =O3 | P27: =G27+H27+K27+L27+M27+N27+O27 | Q27: 模组单价见规格单价表；箱体/电源见本册价目
A28: 4.2 | D28: 310F5 /2R1G1B | E28: =E27 | G28: =E28*F28 | H28: =H27 | I28: =I27 | J28: =J27 | K28: =J28*I28 | L28: =L27 | M28: =M27 | N28: =N27 | O28: =O27 | P28: =G28+H28+K28+L28+M28+N28+O28 | Q28: 模组单价见规格单价表；箱体/电源见本册价目
A29: 4.3 | D29: 310F5 /3R2G | E29: =E28 | G29: =E29*F29 | H29: =H28 | I29: =I28 | J29: =J28 | K29: =J29*I29 | L29: =L28 | M29: =M28 | N29: =N28 | O29: =O28 | P29: =G29+H29+K29+L29+M29+N29+O29 | Q29: 模组单价见规格单价表；箱体/电源见本册价目
A30: 4.4 | D30: 310F5 /3R2G1B | E30: =E29 | G30: =E30*F30 | H30: =H29 | I30: =I29 | J30: =J29 | K30: =J30*I30 | L30: =L29 | M30: =M29 | N30: =N29 | O30: =O29 | P30: =G30+H30+K30+L30+M30+N30+O30 | Q30: 模组单价见规格单价表；箱体/电源见本册价目
A31: 4.5 | D31: 310F5 /4R2G | E31: =E30 | G31: =E31*F31 | H31: =H30 | I31: =I30 | J31: =J30 | K31: =J31*I31 | L31: =L30 | M31: =M30 | N31: =N30 | O31: =O30 | P31: =G31+H31+K31+L31+M31+N31+O31 | Q31: 模组单价见规格单价表；箱体/电源见本册价目
A32: 4.6 | B32: 镀锌钢板箱体含包边 | C32: 1m | D32: 310F5 /2R1G | E32: 8 | F32: =F27 | G32: =E32*F32 | H32: =H5 | I32: =I5 | J32: =电源!G10 | K32: =K5 | L32: =L5 | M32: =M5 | N32: =N5 | O32: =O5 | P32: =G32+H32+K32+L32+M32+N32+O32 | Q32: 模组单价见规格单价表；箱体/电源见本册价目
A33: 4.7 | D33: 310F5 /2R1G1B | E33: =E32 | F33: =F28 | G33: =E33*F33 | H33: =H32 | I33: =I32 | J33: =J32 | K33: =J33*I33 | L33: =L32 | M33: =M32 | N33: =N32 | O33: =O32 | P33: =G33+H33+K33+L33+M33+N33+O33 | Q33: 模组单价见规格单价表；箱体/电源见本册价目
A34: 4.8 | D34: 310F5 /3R2G | E34: =E33 | F34: =F29 | G34: =E34*F34 | H34: =H33 | I34: =I33 | J34: =J33 | K34: =J34*I34 | L34: =L33 | M34: =M33 | N34: =N33 | O34: =O33 | P34: =G34+H34+K34+L34+M34+N34+O34 | Q34: 模组单价见规格单价表；箱体/电源见本册价目
A35: 4.9 | D35: 310F5 /3R2G1B | E35: =E34 | F35: =F30 | G35: =E35*F35 | H35: =H34 | I35: =I34 | J35: =J34 | K35: =J35*I35 | L35: =L34 | M35: =M34 | N35: =N34 | O35: =O34 | P35: =G35+H35+K35+L35+M35+N35+O35 | Q35: 模组单价见规格单价表；箱体/电源见本册价目
A36: 4.10 | D36: 310F5 /4R2G | E36: =E35 | F36: =F31 | G36: =E36*F36 | H36: =H35 | I36: =I35 | J36: =J35 | K36: =J36*I36 | L36: =L35 | M36: =M35 | N36: =N35 | O36: =O35 | P36: =G36+H36+K36+L36+M36+N36+O36 | Q36: 模组单价见规格单价表；箱体/电源见本册价目
A37: P31.25情报板屏单价(1㎡单价)
A38: 序号 | B38: 材料 | C38: 高度屏体安装高度 | D38: 灯珠 | E38: 1㎡模组数量 | F38: 模组单价 | G38: 1㎡模组价格合计 | H38: 箱体单价 | I38: 常规电源数量 | J38: 电源单价 | K38: 电源合计 | L38: 安装支架（选配） | M38: 安装抱箍和螺钉 | N38: 包材 | O38: 辅材 | P38: 总计 | Q38: 备注
A39: 5.1 | B39: 压铸铝箱体不含包边（含包边加110元/㎡） | C39: 1m | D39: 310F5 /2R1G | E39: 8 | G39: =E39*F39 | H39: =H3 | I39: =I3 | J39: =电源!G10 | K39: =K3 | L39: =L3 | M39: =M3 | N39: =N3 | O39: =O3 | P39: =G39+H39+K39+L39+M39+N39+O39 | Q39: 模组单价见规格单价表；箱体/电源见本册价目
A40: 5.2 | D40: 310F5 /2R1G1B | E40: =E39 | G40: =E40*F40 | H40: =H39 | I40: =I39 | J40: =J39 | K40: =J40*I40 | L40: =L39 | M40: =M39 | N40: =N39 | O40: =O39 | P40: =G40+H40+K40+L40+M40+N40+O40 | Q40: 模组单价见规格单价表；箱体/电源见本册价目
...
