Workbook

Sheet 说明
A1: 本文件按模版整理自材料成本.xlsx。原表有数字的单价已转入，无数留空。不含供应商表。表头在第 4 行，数据从第 5 行起。
A3: 这份表给人维护价格用。系统报价时来这里取数，不在核算模板里再抄一遍单价。
A4: 蓝色字是要填写的数。绿色字是公式，不要手改。黄色行是示例，填真实数据前请改掉或删除。
A5: 调价时直接改正文单价，或另存历史副本。本模版不维护「是否当前」「生效日期」。
A6: 供应商名称只填在「供应商」表。报价不读取该表。
A7: 详细步骤见同目录《填写说明.md》。
A9: 工作表 | B9: 谁填、填什么
A10: 灯珠单价 | B10: 成本维护人填写红、绿、蓝灯珠的含税单价。按灯珠批次分行。
A11: 套件单价 | B11: 成本维护人填写底壳、面罩、胶圈。套件合计由公式算出。按点间距和工艺分行。
A12: 模组价格 | B12: 成本维护人填写规格、灯珠颗数和加工费。灯珠单价和套件单价从前面两张表取来，含税单价由公式算出。单面灌胶的灌胶加价填 0，双面填加价。
A13: 箱体单价 | B13: 成本维护人按箱体名称填写含税单价。名称要和核算模板里写的一致。
A14: 核算模板 | B14: 填写某种情报板用哪种模组、每平方米用多少电源、接收卡和辅料，以及含不含立柱、抱箍、支架、控制箱。这里不填模组单价。绿色的「当前模组含税单价」用来核对能否在模组价格表里找到这一行。
A15: 供应商 | B15: 只给内部留底。报价不读这张表。

Sheet 灯珠单价
A2: 按灯珠批次分行。单价为含税。同一批次只保留一行有效价；本表不维护是否当前/生效日期。
A4: 灯珠批次 | B4: R单价 | C4: G单价 | D4: B单价 | E4: 备注
A5: 批次-510
A6: 批次-310

Sheet 套件单价
A2: 按点间距和工艺分行。绿色套件合计不要手改。本表不维护是否当前/生效日期。
A4: 点间距_mm | B4: 工艺 | C4: 底壳单价 | D4: 面罩数量 | E4: 面罩单价 | F4: 胶圈单价 | G4: 套件合计 | H4: 备注
A5: 10.416 | B5: 贴片 | G5: =IF(A5="","",C5+D5*E5+F5)
A6: 10.416 | B6: 直插 | G6: =IF(A6="","",C6+D6*E6+F6)
A7: 15.625 | G7: =IF(A7="","",C7+D7*E7+F7)
A8: 20.833 | G8: =IF(A8="","",C8+D8*E8+F8)
A9: 25 | G9: =IF(A9="","",C9+D9*E9+F9)
A10: 31.25 | G10: =IF(A10="","",C10+D10*E10+F10)
G11: =IF(C11="","",E11+F11*G11+H11)
G12: =IF(C12="","",E12+F12*G12+H12)
G13: =IF(C13="","",E13+F13*G13+H13)
G14: =IF(C14="","",E14+F14*G14+H14)
G15: =IF(C15="","",E15+F15*G15+H15)
G16: =IF(C16="","",E16+F16*G16+H16)
G17: =IF(C17="","",E17+F17*G17+H17)
G18: =IF(C18="","",E18+F18*G18+H18)
G19: =IF(C19="","",E19+F19*G19+H19)
G20: =IF(C20="","",E20+F20*G20+H20)

Sheet 模组价格
A2: 一行一个规格。单面与双面灌胶同属一行：填加工费和灌胶加价后，含税单价_单面＝灯珠合计＋加工费＋套件单价；含税单价_双面＝单面＋灌胶加价。R/G/B单价从「灯珠单价」按批次取，套件单价从「套件单价」按点间距和工艺取。本表不维护是否当前/生效日期。
A4: 名称 | B4: 点间距_mm | C4: 配比 | D4: 灯珠芯片 | E4: 驱动芯片 | F4: 亮度_cd每平方米 | G4: 模组宽_mm | H4: 模组高_mm | I4: 色品 | J4: 灯珠批次 | K4: 工艺 | L4: R数量 | M4: G数量 | N4: B数量 | O4: R单价 | P4: G单价 | Q4: B单价 | R4: 灯珠合计 | S4: 加工费 | T4: 套件单价 | U4: 灌胶加价 | V4: 含税单价_单面 | W4: 含税单价_双面 | X4: 备注
A5: P33.33 | B5: 33.33 | C5: 4R2G | D5: 晶元金线 | E5: 5034B | F5: 15000 | G5: 266.64 | H5: 133.32 | I5: 黄色 | J5: 批次-510 | K5: 贴片 | L5: 128 | M5: 64 | O5: =IF(J5="","",SUMIFS(灯珠单价!B:B,灯珠单价!A:A,J5)) | P5: =IF(J5="","",SUMIFS(灯珠单价!C:C,灯珠单价!A:A,J5)) | Q5: =IF(J5="","",SUMIFS(灯珠单价!D:D,灯珠单价!A:A,J5)) | R5: =IF(B5="","",L5*O5+M5*P5+N5*Q5) | T5: =IF(B5="","",SUMIFS(套件单价!G:G,套件单价!A:A,B5,套件单价!B:B,K5)) | U5: 1.5 | V5: =IF(B5="","",R5+S5+T5) | W5: =IF(B5="","",V5+U5)
A6: P33.33 | B6: 33.33 | C6: 4R2G1B | D6: 晶元金线 | E6: 5034B | F6: 15000 | G6: 266.64 | H6: 133.32 | I6: 黄白 | J6: 批次-510 | K6: 贴片 | L6: 128 | M6: 64 | N6: 32 | O6: =IF(J6="","",SUMIFS(灯珠单价!B:B,灯珠单价!A:A,J6)) | P6: =IF(J6="","",SUMIFS(灯珠单价!C:C,灯珠单价!A:A,J6)) | Q6: =IF(J6="","",SUMIFS(灯珠单价!D:D,灯珠单价!A:A,J6)) | R6: =IF(B6="","",L6*O6+M6*P6+N6*Q6) | T6: =IF(B6="","",SUMIFS(套件单价!G:G,套件单价!A:A,B6,套件单价!B:B,K6)) | U6: 1.5 | V6: =IF(B6="","",R6+S6+T6) | W6: =IF(B6="","",V6+U6)
A7: P33.33 | B7: 33.33 | C7: 3R2G | D7: 晶元金线 | E7: 5034B | F7: 15000 | G7: 266.64 | H7: 133.32 | I7: 黄色 | J7: 批次-510 | K7: 贴片 | L7: 96 | M7: 64 | O7: =IF(J7="","",SUMIFS(灯珠单价!B:B,灯珠单价!A:A,J7)) | P7: =IF(J7="","",SUMIFS(灯珠单价!C:C,灯珠单价!A:A,J7)) | Q7: =IF(J7="","",SUMIFS(灯珠单价!D:D,灯珠单价!A:A,J7)) | R7: =IF(B7="","",L7*O7+M7*P7+N7*Q7) | T7: =IF(B7="","",SUMIFS(套件单价!G:G,套件单价!A:A,B7,套件单价!B:B,K7)) | U7: 1.5 | V7: =IF(B7="","",R7+S7+T7) | W7: =IF(B7="","",V7+U7)
A8: P33.33 | B8: 33.33 | C8: 2R1G | D8: 晶元金线 | E8: 5034B | F8: 15000 | G8: 266.64 | H8: 133.32 | I8: 黄色 | J8: 批次-510 | K8: 贴片 | L8: 64 | M8: 32 | O8: =IF(J8="","",SUMIFS(灯珠单价!B:B,灯珠单价!A:A,J8)) | P8: =IF(J8="","",SUMIFS(灯珠单价!C:C,灯珠单价!A:A,J8)) | Q8: =IF(J8="","",SUMIFS(灯珠单价!D:D,灯珠单价!A:A,J8)) | R8: =IF(B8="","",L8*O8+M8*P8+N8*Q8) | T8: =IF(B8="","",SUMIFS(套件单价!G:G,套件单价!A:A,B8,套件单价!B:B,K8)) | U8: 1.5 | V8: =IF(B8="","",R8+S8+T8) | W8: =IF(B8="","",V8+U8)
A9: P31.25 | B9: 31.25 | C9: 4R2G | D9: 晶元金线 | E9: 5034B | F9: 15000 | G9: 250 | H9: 250 | I9: 黄色 | J9: 批次-510 | K9: 贴片 | L9: 256 | M9: 128 | O9: =IF(J9="","",SUMIFS(灯珠单价!B:B,灯珠单价!A:A,J9)) | P9: =IF(J9="","",SUMIFS(灯珠单价!C:C,灯珠单价!A:A,J9)) | Q9: =IF(J9="","",SUMIFS(灯珠单价!D:D,灯珠单价!A:A,J9)) | R9: =IF(B9="","",L9*O9+M9*P9+N9*Q9) | T9: =IF(B9="","",SUMIFS(套件单价!G:G,套件单价!A:A,B9,套件单价!B:B,K9)) | U9: 3.5 | V9: =IF(B9="","",R9+S9+T9) | W9: =IF(B9="","",V9+U9)
A10: P31.25 | B10: 31.25 | C10: 4R2G1B | D10: 晶元金线 | E10: 5034B | F10: 15000 | G10: 250 | H10: 250 | I10: 黄白 | J10: 批次-510 | K10: 贴片 | L10: 256 | M10: 128 | N10: 64 | O10: =IF(J10="","",SUMIFS(灯珠单价!B:B,灯珠单价!A:A,J10)) | P10: =IF(J10="","",SUMIFS(灯珠单价!C:C,灯珠单价!A:A,J10)) | Q10: =IF(J10="","",SUMIFS(灯珠单价!D:D,灯珠单价!A:A,J10)) | R10: =IF(B10="","",L10*O10+M10*P10+N10*Q10) | T10: =IF(B10="","",SUMIFS(套件单价!G:G,套件单价!A:A,B10,套件单价!B:B,K10)) | U10: 3.5 | V10: =IF(B10="","",R10+S10+T10) | W10: =IF(B10="","",V10+U10)
A11: P31.25 | B11: 31.25 | C11: 3R2G | D11: 晶元金线 | E11: 5034B | F11: 15000 | G11: 250 | H11: 250 | I11: 黄色 | J11: 批次-510 | K11: 贴片 | L11: 192 | M11: 128 | O11: =IF(J11="","",SUMIFS(灯珠单价!B:B,灯珠单价!A:A,J11)) | P11: =IF(J11="","",SUMIFS(灯珠单价!C:C,灯珠单价!A:A,J11)) | Q11: =IF(J11="","",SUMIFS(灯珠单价!D:D,灯珠单价!A:A,J11)) | R11: =IF(B11="","",L11*O11+M11*P11+N11*Q11) | T11: =IF(B11="","",SUMIFS(套件单价!G:G,套件单价!A:A,B11,套件单价!B:B,K11)) | U11: 3.5 | V11: =IF(B11="","",R11+S11+T11) | W11: =IF(B11="","",V11+U11)
A12: P31.25 | B12: 31.25 | C12: 3R2G1B | D12: 晶元金线 | E12: 5034B | F12: 15000 | G12: 250 | H12: 250 | I12: 黄白 | J12: 批次-510 | K12: 贴片 | L12: 192 | M12: 128 | N12: 64 | O12: =IF(J12="","",SUMIFS(灯珠单价!B:B,灯珠单价!A:A,J12)) | P12: =IF(J12="","",SUMIFS(灯珠单价!C:C,灯珠单价!A:A,J12)) | Q12: =IF(J12="","",SUMIFS(灯珠单价!D:D,灯珠单价!A:A,J12)) | R12: =IF(B12="","",L12*O12+M12*P12+N12*Q12) | T12: =IF(B12="","",SUMIFS(套件单价!G:G,套件单价!A:A,B12,套件单价!B:B,K12)) | U12: 3.5 | V12: =IF(B12="","",R12+S12+T12) | W12: =IF(B12="","",V12+U12)
A13: P31.25 | B13: 31.25 | C13: 2R1G | D13: 晶元金线 | E13: 5034B | F13: 15000 | G13: 250 | H13: 250 | I13: 黄色 | J13: 批次-510 | K13: 贴片 | L13: 128 | M13: 64 | O13: =IF(J13="","",SUMIFS(灯珠单价!B:B,灯珠单价!A:A,J13)) | P13: =IF(J13="","",SUMIFS(灯珠单价!C:C,灯珠单价!A:A,J13)) | Q13: =IF(J13="","",SUMIFS(灯珠单价!D:D,灯珠单价!A:A,J13)) | R13: =IF(B13="","",L13*O13+M13*P13+N13*Q13) | T13: =IF(B13="","",SUMIFS(套件单价!G:G,套件单价!A:A,B13,套件单价!B:B,K13)) | U13: 3.5 | V13: =IF(B13="","",R13+S13+T13) | W13: =IF(B13="","",V13+U13)
A14: P31.25 | B14: 31.25 | C14: 2R1G1B | D14: 晶元金线 | E14: 5034B | F14: 15000 | G14: 250 | H14: 250 | I14: 黄白 | J14: 批次-510 | K14: 贴片 | L14: 128 | M14: 64 | N14: 64 | O14: =IF(J14="","",SUMIFS(灯珠单价!B:B,灯珠单价!A:A,J14)) | P14: =IF(J14="","",SUMIFS(灯珠单价!C:C,灯珠单价!A:A,J14)) | Q14: =IF(J14="","",SUMIFS(灯珠单价!D:D,灯珠单价!A:A,J14)) | R14: =IF(B14="","",L14*O14+M14*P14+N14*Q14) | T14: =IF(B14="","",SUMIFS(套件单价!G:G,套件单价!A:A,B14,套件单价!B:B,K14)) | U14: 3.5 | V14: =IF(B14="","",R14+S14+T14) | W14: =IF(B14="","",V14+U14)
A15: P25 | B15: 25 | C15: 4R2G | D15: 晶元金线 | E15: 5034B | F15: 15000 | G15: 200 | H15: 200 | I15: 黄色 | J15: 批次-510 | K15: 贴片 | L15: 256 | M15: 128 | O15: =IF(J15="","",SUMIFS(灯珠单价!B:B,灯珠单价!A:A,J15)) | P15: =IF(J15="","",SUMIFS(灯珠单价!C:C,灯珠单价!A:A,J15)) | Q15: =IF(J15="","",SUMIFS(灯珠单价!D:D,灯珠单价!A:A,J15)) | R15: =IF(B15="","",L15*O15+M15*P15+N15*Q15) | T15: =IF(B15="","",SUMIFS(套件单价!G:G,套件单价!A:A,B15,套件单价!B:B,K15)) | U15: 2.5 | V15: =IF(B15="","",R15+S15+T15) | W15: =IF(B15="","",V15+U15)
A16: P25 | B16: 25 | C16: 3R2G | D16: 晶元金线 | E16: 5034B | F16: 15000 | G16: 200 | H16: 200 | I16: 黄色 | J16: 批次-510 | K16: 贴片 | L16: 192 | M16: 128 | O16: =IF(J16="","",SUMIFS(灯珠单价!B:B,灯珠单价!A:A,J16)) | P16: =IF(J16="","",SUMIFS(灯珠单价!C:C,灯珠单价!A:A,J16)) | Q16: =IF(J16="","",SUMIFS(灯珠单价!D:D,灯珠单价!A:A,J16)) | R16: =IF(B16="","",L16*O16+M16*P16+N16*Q16) | T16: =IF(B16="","",SUMIFS(套件单价!G:G,套件单价!A:A,B16,套件单价!B:B,K16)) | U16: 2.5 | V16: =IF(B16="","",R16+S16+T16) | W16: =IF(B16="","",V16+U16)
A17: P25 | B17: 25 | C17: 3R2G1B | D17: 晶元金线 | E17: 5034B | F17: 15000 | G17: 200 | H17: 200 | I17: 黄白 | J17: 批次-510 | K17: 贴片 | L17: 192 | M17: 128 | N17: 64 | O17: =IF(J17="","",SUMIFS(灯珠单价!B:B,灯珠单价!A:A,J17)) | P17: =IF(J17="","",SUMIFS(灯珠单价!C:C,灯珠单价!A:A,J17)) | Q17: =IF(J17="","",SUMIFS(灯珠单价!D:D,灯珠单价!A:A,J17)) | R17: =IF(B17="","",L17*O17+M17*P17+N17*Q17) | T17: =IF(B17="","",SUMIFS(套件单价!G:G,套件单价!A:A,B17,套件单价!B:B,K17)) | U17: 2.5 | V17: =IF(B17="","",R17+S17+T17) | W17: =IF(B17="","",V17+U17)
A18: P25 | B18: 25 | C18: 2R1G | D18: 晶元金线 | E18: 5034B | F18: 15000 | G18: 200 | H18: 200 | I18: 黄色 | J18: 批次-510 | K18: 贴片 | L18: 128 | M18: 64 | O18: =IF(J18="","",SUMIFS(灯珠单价!B:B,灯珠单价!A:A,J18)) | P18: =IF(J18="","",SUMIFS(灯珠单价!C:C,灯珠单价!A:A,J18)) | Q18: =IF(J18="","",SUMIFS(灯珠单价!D:D,灯珠单价!A:A,J18)) | R18: =IF(B18="","",L18*O18+M18*P18+N18*Q18) | T18: =IF(B18="","",SUMIFS(套件单价!G:G,套件单价!A:A,B18,套件单价!B:B,K18)) | U18: 2.5 | V18: =IF(B18="","",R18+S18+T18) | W18: =IF(B18="","",V18+U18)
A19: P25 | B19: 25 | C19: 2R1G1B | D19: 晶元金线 | E19: 5034B | F19: 15000 | G19: 200 | H19: 200 | I19: 黄白 | J19: 批次-510 | K19: 贴片 | L19: 128 | M19: 64 | N19: 64 | O19: =IF(J19="","",SUMIFS(灯珠单价!B:B,灯珠单价!A:A,J19)) | P19: =IF(J19="","",SUMIFS(灯珠单价!C:C,灯珠单价!A:A,J19)) | Q19: =IF(J19="","",SUMIFS(灯珠单价!D:D,灯珠单价!A:A,J19)) | R19: =IF(B19="","",L19*O19+M19*P19+N19*Q19) | T19: =IF(B19="","",SUMIFS(套件单价!G:G,套件单价!A:A,B19,套件单价!B:B,K19)) | U19: 2.5 | V19: =IF(B19="","",R19+S19+T19) | W19: =IF(B19="","",V19+U19)
A20: P20 | B20: 20 | C20: 2R1G | D20: 晶元金线 | E20: 5034B | F20: 15000 | G20: 320 | H20: 160 | I20: 黄色 | J20: 批次-510 | K20: 贴片 | L20: 256 | M20: 128 | O20: =IF(J20="","",SUMIFS(灯珠单价!B:B,灯珠单价!A:A,J20)) | P20: =IF(J20="","",SUMIFS(灯珠单价!C:C,灯珠单价!A:A,J20)) | Q20: =IF(J20="","",SUMIFS(灯珠单价!D:D,灯珠单价!A:A,J20)) | R20: =IF(B20="","",L20*O20+M20*P20+N20*Q20) | T20: =IF(B20="","",SUMIFS(套件单价!G:G,套件单价!A:A,B20,套件单价!B:B,K20)) | U20: 3 | V20: =IF(B20="","",R20+S20+T20) | W20: =IF(B20="","",V20+U20)
A21: P20 | B21: 20 | C21: 1R1G1B | D21: 晶元金线 | E21: 5034B | F21: 15000 | G21: 320 | H21: 160 | I21: 黄白 | J21: 批次-510 | K21: 贴片 | L21: 128 | M21: 128 | N21: 128 | O21: =IF(J21="","",SUMIFS(灯珠单价!B:B,灯珠单价!A:A,J21)) | P21: =IF(J21="","",SUMIFS(灯珠单价!C:C,灯珠单价!A:A,J21)) | Q21: =IF(J21="","",SUMIFS(灯珠单价!D:D,灯珠单价!A:A,J21)) | R21: =IF(B21="","",L21*O21+M21*P21+N21*Q21) | T21: =IF(B21="","",SUMIFS(套件单价!G:G,套件单价!A:A,B21,套件单价!B:B,K21)) | U21: 3 | V21: =IF(B21="","",R21+S21+T21) | W21: =IF(B21="","",V21+U21)
A22: P20 | B22: 20 | C22: 2R1G1B | D22: 晶元金线 | E22: 5034B | F22: 15000 | G22: 320 | H22: 160 | I22: 黄白 | J22: 批次-510 | K22: 贴片 | L22: 256 | M22: 128 | N22: 128 | O22: =IF(J22="","",SUMIFS(灯珠单价!B:B,灯珠单价!A:A,J22)) | P22: =IF(J22="","",SUMIFS(灯珠单价!C:C,灯珠单价!A:A,J22)) | Q22: =IF(J22="","",SUMIFS(灯珠单价!D:D,灯珠单价!A:A,J22)) | R22: =IF(B22="","",L22*O22+M22*P22+N22*Q22) | T22: =IF(B22="","",SUMIFS(套件单价!G:G,套件单价!A:A,B22,套件单价!B:B,K22)) | U22: 3 | V22: =IF(B22="","",R22+S22+T22) | W22: =IF(B22="","",V22+U22)
A23: P16 | B23: 16 | C23: 2R1G | D23: 晶元金线 | E23: 5034B | F23: 15000 | G23: 256 | H23: 256 | I23: 黄色 | J23: 批次-510 | K23: 贴片 | L23: 512 | M23: 256 | O23: =IF(J23="","",SUMIFS(灯珠单价!B:B,灯珠单价!A:A,J23)) | P23: =IF(J23="","",SUMIFS(灯珠单价!C:C,灯珠单价!A:A,J23)) | Q23: =IF(J23="","",SUMIFS(灯珠单价!D:D,灯珠单价!A:A,J23)) | R23: =IF(B23="","",L23*O23+M23*P23+N23*Q23) | T23: =IF(B23="","",SUMIFS(套件单价!G:G,套件单价!A:A,B23,套件单价!B:B,K23)) | U23: 3.5 | V23: =IF(B23="","",R23+S23+T23) | W23: =IF(B23="","",V23+U23)
A24: P16 | B24: 16 | C24: 1R1G1B | D24: 晶元金线 | E24: 5034B | F24: 15000 | G24: 256 | H24: 256 | I24: 黄白 | J24: 批次-510 | K24: 贴片 | L24: 256 | M24: 256 | N24: 256 | O24: =IF(J24="","",SUMIFS(灯珠单价!B:B,灯珠单价!A:A,J24)) | P24: =IF(J24="","",SUMIFS(灯珠单价!C:C,灯珠单价!A:A,J24)) | Q24: =IF(J24="","",SUMIFS(灯珠单价!D:D,灯珠单价!A:A,J24)) | R24: =IF(B24="","",L24*O24+M24*P24+N24*Q24) | T24: =IF(B24="","",SUMIFS(套件单价!G:G,套件单价!A:A,B24,套件单价!B:B,K24)) | U24: 3.5 | V24: =IF(B24="","",R24+S24+T24) | W24: =IF(B24="","",V24+U24)
A25: P16 | B25: 16 | C25: 2R1G1B | D25: 晶元金线 | E25: 5034B | F25: 15000 | G25: 256 | H25: 256 | I25: 黄白 | J25: 批次-510 | K25: 贴片 | L25: 512 | M25: 256 | N25: 256 | O25: =IF(J25="","",SUMIFS(灯珠单价!B:B,灯珠单价!A:A,J25)) | P25: =IF(J25="","",SUMIFS(灯珠单价!C:C,灯珠单价!A:A,J25)) | Q25: =IF(J25="","",SUMIFS(灯珠单价!D:D,灯珠单价!A:A,J25)) | R25: =IF(B25="","",L25*O25+M25*P25+N25*Q25) | T25: =IF(B25="","",SUMIFS(套件单价!G:G,套件单价!A:A,B25,套件单价!B:B,K25)) | U25: 3.5 | V25: =IF(B25="","",R25+S25+T25) | W25: =IF(B25="","",V25+U25)
A26: P31.25 | B26: 31.25 | C26: 4R2G | D26: 晶元金线 | E26: 5034B | F26: 15000 | G26: 250 | H26: 250 | I26: 黄色 | J26: 批次-310 | K26: 贴片 | L26: 256 | M26: 128 | O26: =IF(J26="","",SUMIFS(灯珠单价!B:B,灯珠单价!A:A,J26)) | P26: =IF(J26="","",SUMIFS(灯珠单价!C:C,灯珠单价!A:A,J26)) | Q26: =IF(J26="","",SUMIFS(灯珠单价!D:D,灯珠单价!A:A,J26)) | R26: =IF(B26="","",L26*O26+M26*P26+N26*Q26) | S26: 111.42 | T26: =IF(B26="","",SUMIFS(套件单价!G:G,套件单价!A:A,B26,套件单价!B:B,K26)) | U26: 3.5 | V26: =IF(B26="","",R26+S26+T26) | W26: =IF(B26="","",V26+U26)
A27: P31.25 | B27: 31.25 | C27: 4R2G1B | D27: 晶元金线 | E27: 5034B | F27: 15000 | G27: 250 | H27: 250 | I27: 黄白 | J27: 批次-310 | K27: 贴片 | L27: 256 | M27: 128 | N27: 64 | O27: =IF(J27="","",SUMIFS(灯珠单价!B:B,灯珠单价!A:A,J27)) | P27: =IF(J27="","",SUMIFS(灯珠单价!C:C,灯珠单价!A:A,J27)) | Q27: =IF(J27="","",SUMIFS(灯珠单价!D:D,灯珠单价!A:A,J27)) | R27: =IF(B27="","",L27*O27+M27*P27+N27*Q27) | S27: 118.58 | T27: =IF(B27="","",SUMIFS(套件单价!G:G,套件单价!A:A,B27,套件单价!B:B,K27)) | U27: 3.5 | V27: =IF(B27="","",R27+S27+T27) | W27: =IF(B27="","",V27+U27)
A28: P31.25 | B28: 31.25 | C28: 3R2G | D28: 晶元金线 | E28: 5034B | F28: 15000 | G28: 250 | H28: 250 | I28: 黄色 | J28: 批次-310 | K28: 贴片 | L28: 192 | M28: 128 | O28: =IF(J28="","",SUMIFS(灯珠单价!B:B,灯珠单价!A:A,J28)) | P28: =IF(J28="","",SUMIFS(灯珠单价!C:C,灯珠单价!A:A,J28)) | Q28: =IF(J28="","",SUMIFS(灯珠单价!D:D,灯珠单价!A:A,J28)) | R28: =IF(B28="","",L28*O28+M28*P28+N28*Q28) | S28: 110.42 | T28: =IF(B28="","",SUMIFS(套件单价!G:G,套件单价!A:A,B28,套件单价!B:B,K28)) | U28: 3.5 | V28: =IF(B28="","",R28+S28+T28) | W28: =IF(B28="","",V28+U28)
A29: P31.25 | B29: 31.25 | C29: 3R2G1B | D29: 晶元金线 | E29: 5034B | F29: 15000 | G29: 250 | H29: 250 | I29: 黄白 | J29: 批次-310 | K29: 贴片 | L29: 192 | M29: 128 | N29: 64 | O29: =IF(J29="","",SUMIFS(灯珠单价!B:B,灯珠单价!A:A,J29)) | P29: =IF(J29="","",SUMIFS(灯珠单价!C:C,灯珠单价!A:A,J29)) | Q29: =IF(J29="","",SUMIFS(灯珠单价!D:D,灯珠单价!A:A,J29)) | R29: =IF(B29="","",L29*O29+M29*P29+N29*Q29) | S29: 117.58 | T29: =IF(B29="","",SUMIFS(套件单价!G:G,套件单价!A:A,B29,套件单价!B:B,K29)) | U29: 3.5 | V29: =IF(B29="","",R29+S29+T29) | W29: =IF(B29="","",V29+U29)
A30: P31.25 | B30: 31.25 | C30: 2R1G | D30: 晶元金线 | E30: 5034B | F30: 15000 | G30: 250 | H30: 250 | I30: 黄色 | J30: 批次-310 | K30: 贴片 | L30: 128 | M30: 64 | O30: =IF(J30="","",SUMIFS(灯珠单价!B:B,灯珠单价!A:A,J30)) | P30: =IF(J30="","",SUMIFS(灯珠单价!C:C,灯珠单价!A:A,J30)) | Q30: =IF(J30="","",SUMIFS(灯珠单价!D:D,灯珠单价!A:A,J30)) | R30: =IF(B30="","",L30*O30+M30*P30+N30*Q30) | S30: 92.52 | T30: =IF(B30="","",SUMIFS(套件单价!G:G,套件单价!A:A,B30,套件单价!B:B,K30)) | U30: 3.5 | V30: =IF(B30="","",R30+S30+T30) | W30: =IF(B30="","",V30+U30)
A31: P31.25 | B31: 31.25 | C31: 2R1G1B | D31: 晶元金线 | E31: 5034B | F31: 15000 | G31: 250 | H31: 250 | I31: 黄白 | J31: 批次-310 | K31: 贴片 | L31: 128 | M31: 64 | N31: 64 | O31: =IF(J31="","",SUMIFS(灯珠单价!B:B,灯珠单价!A:A,J31)) | P31: =IF(J31="","",SUMIFS(灯珠单价!C:C,灯珠单价!A:A,J31)) | Q31: =IF(J31="","",SUMIFS(灯珠单价!D:D,灯珠单价!A:A,J31)) | R31: =IF(B31="","",L31*O31+M31*P31+N31*Q31) | S31: 106.38 | T31: =IF(B31="","",SUMIFS(套件单价!G:G,套件单价!A:A,B31,套件单价!B:B,K31)) | U31: 3.5 | V31: =IF(B31="","",R31+S31+T31) | W31: =IF(B31="","",V31+U31)
A32: P25 | B32: 25 | C32: 4R2G | D32: 晶元金线 | E32: 5034B | F32: 15000 | G32: 200 | H32: 200 | I32: 黄色 | J32: 批次-310 | K32: 贴片 | L32: 256 | M32: 128 | O32: =IF(J32="","",SUMIFS(灯珠单价!B:B,灯珠单价!A:A,J32)) | P32: =IF(J32="","",SUMIFS(灯珠单价!C:C,灯珠单价!A:A,J32)) | Q32: =IF(J32="","",SUMIFS(灯珠单价!D:D,灯珠单价!A:A,J32)) | R32: =IF(B32="","",L32*O32+M32*P32+N32*Q32) | S32: 90.27 | T32: =IF(B32="","",SUMIFS(套件单价!G:G,套件单价!A:A,B32,套件单价!B:B,K32)) | U32: 2.5 | V32: =IF(B32="","",R32+S32+T32) | W32: =IF(B32="","",V32+U32)
A33: P25 | B33: 25 | C33: 4R2G1B | D33: 晶元金线 | E33: 5034B | F33: 15000 | G33: 200 | H33: 200 | I33: 黄白 | J33: 批次-310 | K33: 贴片 | L33: 256 | M33: 128 | N33: 64 | O33: =IF(J33="","",SUMIFS(灯珠单价!B:B,灯珠单价!A:A,J33)) | P33: =IF(J33="","",SUMIFS(灯珠单价!C:C,灯珠单价!A:A,J33)) | Q33: =IF(J33="","",SUMIFS(灯珠单价!D:D,灯珠单价!A:A,J33)) | R33: =IF(B33="","",L33*O33+M33*P33+N33*Q33) | T33: =IF(B33="","",SUMIFS(套件单价!G:G,套件单价!A:A,B33,套件单价!B:B,K33)) | V33: =IF(B33="","",R33+S33+T33) | W33: =IF(B33="","",V33+U33)
A34: P25 | B34: 25 | C34: 3R2G | D34: 晶元金线 | E34: 5034B | F34: 15000 | G34: 200 | H34: 200 | I34: 黄色 | J34: 批次-310 | K34: 贴片 | L34: 192 | M34: 128 | O34: =IF(J34="","",SUMIFS(灯珠单价!B:B,灯珠单价!A:A,J34)) | P34: =IF(J34="","",SUMIFS(灯珠单价!C:C,灯珠单价!A:A,J34)) | Q34: =IF(J34="","",SUMIFS(灯珠单价!D:D,灯珠单价!A:A,J34)) | R34: =IF(B34="","",L34*O34+M34*P34+N34*Q34) | S34: 89.37 | T34: =IF(B34="","",SUMIFS(套件单价!G:G,套件单价!A:A,B34,套件单价!B:B,K34)) | U34: 2.5 | V34: =IF(B34="","",R34+S34+T34) | W34: =IF(B34="","",V34+U34)
A35: P25 | B35: 25 | C35: 3R2G1B | D35: 晶元金线 | E35: 5034B | F35: 15000 | G35: 200 | H35: 200 | I35: 黄白 | J35: 批次-310 | K35: 贴片 | L35: 192 | M35: 128 | N35: 64 | O35: =IF(J35="","",SUMIFS(灯珠单价!B:B,灯珠单价!A:A,J35)) | P35: =IF(J35="","",SUMIFS(灯珠单价!C:C,灯珠单价!A:A,J35)) | Q35: =IF(J35="","",SUMIFS(灯珠单价!D:D,灯珠单价!A:A,J35)) | R35: =IF(B35="","",L35*O35+M35*P35+N35*Q35) | S35: 96.53 | T35: =IF(B35="","",SUMIFS(套件单价!G:G,套件单价!A:A,B35,套件单价!B:B,K35)) | U35: 2.5 | V35: =IF(B35="","",R35+S35+T35) | W35: =IF(B35="","",V35+U35)
A36: P25 | B36: 25 | C36: 2R1G | D36: 晶元金线 | E36: 5034B | F36: 15000 | G36: 200 | H36: 200 | I36: 黄色 | J36: 批次-310 | K36: 贴片 | L36: 128 | M36: 64 | O36: =IF(J36="","",SUMIFS(灯珠单价!B:B,灯珠单价!A:A,J36)) | P36: =IF(J36="","",SUMIFS(灯珠单价!C:C,灯珠单价!A:A,J36)) | Q36: =IF(J36="","",SUMIFS(灯珠单价!D:D,灯珠单价!A:A,J36)) | R36: =IF(B36="","",L36*O36+M36*P36+N36*Q36) | S36: 80.17 | T36: =IF(B36="","",SUMIFS(套件单价!G:G,套件单价!A:A,B36,套件单价!B:B,K36)) | U36: 2.5 | V36: =IF(B36="","",R36+S36+T36) | W36: =IF(B36="","",V36+U36)
A37: P25 | B37: 25 | C37: 2R1G1B | D37: 晶元金线 | E37: 5034B | F37: 15000 | G37: 200 | H37: 200 | I37: 黄白 | J37: 批次-310 | K37: 贴片 | L37: 128 | M37: 64 | N37: 64 | O37: =IF(J37="","",SUMIFS(灯珠单价!B:B,灯珠单价!A:A,J37)) | P37: =IF(J37="","",SUMIFS(灯珠单价!C:C,灯珠单价!A:A,J37)) | Q37: =IF(J37="","",SUMIFS(灯珠单价!D:D,灯珠单价!A:A,J37)) | R37: =IF(B37="","",L37*O37+M37*P37+N37*Q37) | S37: 85.33 | T37: =IF(B37="","",SUMIFS(套件单价!G:G,套件单价!A:A,B37,套件单价!B:B,K37)) | U37: 2.5 | V37: =IF(B37="","",R37+S37+T37) | W37: =IF(B37="","",V37+U37)
A38: P20 | B38: 20 | C38: 2R1G | D38: 晶元金线 | E38: 5034B | F38: 15000 | G38: 320 | H38: 160 | I38: 黄色 | J38: 批次-310 | K38: 贴片 | L38: 256 | M38: 128 | O38: =IF(J38="","",SUMIFS(灯珠单价!B:B,灯珠单价!A:A,J38)) | P38: =IF(J38="","",SUMIFS(灯珠单价!C:C,灯珠单价!A:A,J38)) | Q38: =IF(J38="","",SUMIFS(灯珠单价!D:D,灯珠单价!A:A,J38)) | R38: =IF(B38="","",L38*O38+M38*P38+N38*Q38) | S38: 95.54 | T38: =IF(B38="","",SUMIFS(套件单价!G:G,套件单价!A:A,B38,套件单价!B:B,K38)) | U38: 3 | V38: =IF(B38="","",R38+S38+T38) | W38: =IF(B38="","",V38+U38)
A39: P20 | B39: 20 | C39: 1R1G1B | D39: 晶元金线 | E39: 5034B | F39: 15000 | G39: 320 | H39: 160 | I39: 黄白 | J39: 批次-310 | K39: 贴片 | L39: 128 | M39: 128 | N39: 128 | O39: =IF(J39="","",SUMIFS(灯珠单价!B:B,灯珠单价!A:A,J39)) | P39: =IF(J39="","",SUMIFS(灯珠单价!C:C,灯珠单价!A:A,J39)) | Q39: =IF(J39="","",SUMIFS(灯珠单价!D:D,灯珠单价!A:A,J39)) | R39: =IF(B39="","",L39*O39+M39*P39+N39*Q39) | S39: 104.16 | T39: =IF(B39="","",SUMIFS(套件单价!G:G,套件单价!A:A,B39,套件单价!B:B,K39)) | U39: 3 | V39: =IF(B39="","",R39+S39+T39) | W39: =IF(B39="","",V39+U39)
A40: P20 | B40: 20 | C40: 2R1G1B | D40: 晶元金线 | E40: 5034B | F40: 15000 | G40: 320 | H40: 160 | I40: 黄白 | J40: 批次-310 | K40: 贴片 | L40: 256 | M40: 128 | N40: 128 | O40: =IF(J40="","",SUMIFS(灯珠单价!B:B,灯珠单价!A:A,J40)) | P40: =IF(J40="","",SUMIFS(灯珠单价!C:C,灯珠单价!A:A,J40)) | Q40: =IF(J40="","",SUMIFS(灯珠单价!D:D,灯珠单价!A:A,J40)) | R40: =IF(B40="","",L40*O40+M40*P40+N40*Q40) | S40: 106.06 | T40: =IF(B40="","",SUMIFS(套件单价!G:G,套件单价!A:A,B40,套件单价!B:B,K40)) | U40: 3 | V40: =IF(B40="","",R40+S40+T40) | W40: =IF(B40="","",V40+U40)
A41: P16 | B41: 16 | C41: 2R1G | D41: 晶元金线 | E41: 5034B | F41: 15000 | G41: 256 | H41: 256 | I41: 黄色 | J41: 批次-310 | K41: 贴片 | L41: 512 | M41: 256 | O41: =IF(J41="","",SUMIFS(灯珠单价!B:B,灯珠单价!A:A,J41)) | P41: =IF(J41="","",SUMIFS(灯珠单价!C:C,灯珠单价!A:A,J41)) | Q41: =IF(J41="","",SUMIFS(灯珠单价!D:D,灯珠单价!A:A,J41)) | R41: =IF(B41="","",L41*O41+M41*P41+N41*Q41) | S41: 137.08 | T41: =IF(B41="","",SUMIFS(套件单价!G:G,套件单价!A:A,B41,套件单价!B:B,K41)) | U41: 3.5 | V41: =IF(B41="","",R41+S41+T41) | W41: =IF(B41="","",V41+U41)
A42: P16 | B42: 16 | C42: 1R1G1B | D42: 晶元金线 | E42: 5034B | F42: 15000 | G42: 256 | H42: 256 | I42: 黄白 | J42: 批次-310 | K42: 贴片 | L42: 256 | M42: 256 | N42: 256 | O42: =IF(J42="","",SUMIFS(灯珠单价!B:B,灯珠单价!A:A,J42)) | P42: =IF(J42="","",SUMIFS(灯珠单价!C:C,灯珠单价!A:A,J42)) | Q42: =IF(J42="","",SUMIFS(灯珠单价!D:D,灯珠单价!A:A,J42)) | R42: =IF(B42="","",L42*O42+M42*P42+N42*Q42) | S42: 153.92 | T42: =IF(B42="","",SUMIFS(套件单价!G:G,套件单价!A:A,B42,套件单价!B:B,K42)) | U42: 3.5 | V42: =IF(B42="","",R42+S42+T42) | W42: =IF(B42="","",V42+U42)
...

Sheet 箱体单价
A2: 箱体名称要和「核算模板」里写的完全一致。本表不维护是否当前/生效日期。
A4: 箱体名称 | B4: 材料 | C4: 安装位置 | D4: 宽_mm | E4: 高_mm | F4: 密封 | G4: 包边 | H4: 含税单价 | I4: 备注
A5: 压铸铝箱体-全密封-含 | B5: 压铸铝 | D5: 1000 | E5: 1000 | F5: 全密封 | G5: 含
A6: 洞内压铸铝箱体-全密封-含 | B6: 压铸铝 | C6: 洞内 | D6: 1000 | E6: 1000 | F6: 全密封 | G6: 含
A7: 压铸铝箱体-后开放-含 | B7: 压铸铝 | D7: 1000 | E7: 1000 | F7: 后开放 | G7: 含
A8: 洞内压铸铝箱体-后开放-含 | B8: 压铸铝 | C8: 洞内 | D8: 1000 | E8: 1000 | F8: 后开放 | G8: 含
A9: 压铸铝箱体-后开放-含 | B9: 压铸铝 | D9: 1000 | E9: 750 | F9: 后开放 | G9: 含
A10: 门架铁箱体-全密封-含 | B10: 铁箱 | C10: 门架 | D10: 1000 | E10: 1000 | F10: 全密封 | G10: 含
A11: 门架铁箱体-全密封-含 | B11: 铁箱 | C11: 门架 | D11: 1000 | E11: 1000 | F11: 全密封 | G11: 含
A12: 悬臂铁箱体-全密封-含 | B12: 铁箱 | C12: 悬臂 | D12: 1000 | E12: 1000 | F12: 全密封 | G12: 含
A13: 悬臂铁箱体-全密封-含 | B13: 铁箱 | C13: 悬臂 | D13: 1000 | E13: 1000 | F13: 全密封 | G13: 含
A14: 洞内铁箱体-全密封-含 | B14: 铁箱 | C14: 洞内 | D14: 1000 | E14: 1000 | F14: 全密封 | G14: 含
A15: 车道屏背抱式-全密封-含 | C15: 车道 | D15: 1000 | E15: 1000 | F15: 全密封 | G15: 含

Sheet 核算模板
A2: 这里写算法，不写模组单价。绿色两列用来核对能否在模组价格表和箱体表里找到对应行。模组含税单价按本行「灌胶」在模组价格的含税单价_单面或_双面中取。辅料按每平方米填写。本表不维护是否当前。
A4: 安装形态 | B4: 点间距_mm | C4: 模组宽_mm | D4: 模组高_mm | E4: 配比 | F4: 驱动芯片 | G4: 灌胶 | H4: 灯珠批次 | I4: 工艺 | J4: 箱体名称 | K4: 每平方米电源数量 | L4: 每平方米接收卡数量 | M4: 每平方米辅料 | N4: 含立柱 | O4: 含抱箍 | P4: 含支架 | Q4: 含控制箱 | R4: 当前模组含税单价 | S4: 当前箱体含税单价 | T4: 备注
R5: =IF(B5="","",IF(G5="双面",SUMIFS(模组价格!W:W,模组价格!B:B,B5,模组价格!C:C,E5,模组价格!G:G,C5,模组价格!H:H,D5,模组价格!J:J,H5),SUMIFS(模组价格!V:V,模组价格!B:B,B5,模组价格!C:C,E5,模组价格!G:G,C5,模组价格!H:H,D5,模组价格!J:J,H5))) | S5: =IF(J5="","",SUMIFS(箱体单价!H:H,箱体单价!A:A,J5))
R6: =IF(B6="","",IF(G6="双面",SUMIFS(模组价格!W:W,模组价格!B:B,B6,模组价格!C:C,E6,模组价格!G:G,C6,模组价格!H:H,D6,模组价格!J:J,H6),SUMIFS(模组价格!V:V,模组价格!B:B,B6,模组价格!C:C,E6,模组价格!G:G,C6,模组价格!H:H,D6,模组价格!J:J,H6))) | S6: =IF(J6="","",SUMIFS(箱体单价!H:H,箱体单价!A:A,J6))
R7: =IF(C7="","",SUMIFS(模组价格!X:X,模组价格!A:A,"是",模组价格!C:C,C7,模组价格!D:D,F7,模组价格!H:H,D7,模组价格!I:I,E7,模组价格!K:K,H7,模组价格!L:L,I7)) | S7: =IF(K7="","",SUMIFS(箱体单价!J:J,箱体单价!A:A,"是",箱体单价!C:C,K7))
R8: =IF(C8="","",SUMIFS(模组价格!X:X,模组价格!A:A,"是",模组价格!C:C,C8,模组价格!D:D,F8,模组价格!H:H,D8,模组价格!I:I,E8,模组价格!K:K,H8,模组价格!L:L,I8)) | S8: =IF(K8="","",SUMIFS(箱体单价!J:J,箱体单价!A:A,"是",箱体单价!C:C,K8))
R9: =IF(C9="","",SUMIFS(模组价格!X:X,模组价格!A:A,"是",模组价格!C:C,C9,模组价格!D:D,F9,模组价格!H:H,D9,模组价格!I:I,E9,模组价格!K:K,H9,模组价格!L:L,I9)) | S9: =IF(K9="","",SUMIFS(箱体单价!J:J,箱体单价!A:A,"是",箱体单价!C:C,K9))
R10: =IF(C10="","",SUMIFS(模组价格!X:X,模组价格!A:A,"是",模组价格!C:C,C10,模组价格!D:D,F10,模组价格!H:H,D10,模组价格!I:I,E10,模组价格!K:K,H10,模组价格!L:L,I10)) | S10: =IF(K10="","",SUMIFS(箱体单价!J:J,箱体单价!A:A,"是",箱体单价!C:C,K10))
R11: =IF(C11="","",SUMIFS(模组价格!X:X,模组价格!A:A,"是",模组价格!C:C,C11,模组价格!D:D,F11,模组价格!H:H,D11,模组价格!I:I,E11,模组价格!K:K,H11,模组价格!L:L,I11)) | S11: =IF(K11="","",SUMIFS(箱体单价!J:J,箱体单价!A:A,"是",箱体单价!C:C,K11))
R12: =IF(C12="","",SUMIFS(模组价格!X:X,模组价格!A:A,"是",模组价格!C:C,C12,模组价格!D:D,F12,模组价格!H:H,D12,模组价格!I:I,E12,模组价格!K:K,H12,模组价格!L:L,I12)) | S12: =IF(K12="","",SUMIFS(箱体单价!J:J,箱体单价!A:A,"是",箱体单价!C:C,K12))
R13: =IF(C13="","",SUMIFS(模组价格!X:X,模组价格!A:A,"是",模组价格!C:C,C13,模组价格!D:D,F13,模组价格!H:H,D13,模组价格!I:I,E13,模组价格!K:K,H13,模组价格!L:L,I13)) | S13: =IF(K13="","",SUMIFS(箱体单价!J:J,箱体单价!A:A,"是",箱体单价!C:C,K13))
R14: =IF(C14="","",SUMIFS(模组价格!X:X,模组价格!A:A,"是",模组价格!C:C,C14,模组价格!D:D,F14,模组价格!H:H,D14,模组价格!I:I,E14,模组价格!K:K,H14,模组价格!L:L,I14)) | S14: =IF(K14="","",SUMIFS(箱体单价!J:J,箱体单价!A:A,"是",箱体单价!C:C,K14))
R15: =IF(C15="","",SUMIFS(模组价格!X:X,模组价格!A:A,"是",模组价格!C:C,C15,模组价格!D:D,F15,模组价格!H:H,D15,模组价格!I:I,E15,模组价格!K:K,H15,模组价格!L:L,I15)) | S15: =IF(K15="","",SUMIFS(箱体单价!J:J,箱体单价!A:A,"是",箱体单价!C:C,K15))
